Workbook
Name Slicer_Analyzer_Module: #N/A

Sheet Analyzer Dashboard
B1: LABORATORY DATA REPORT: JUNE 1-6, 2026
D2: =Pivots!G13 -> 0 | I2: =Pivots!F12 -> 0 | N2: =Pivots!F25 -> 0 | S2: =Pivots!F24 -> 20
D4: =Pivots!G19 -> 0 | I4: =Pivots!F18 -> 0 | N4: =Pivots!F31 -> 0 | S4: =Pivots!F30 -> 1
AM23: =IF(Pivots!#REF!=" ",0,Pivots!#REF!) -> #REF! | AN23: =IF(Pivots!#REF!=" ",0,Pivots!#REF!) -> #REF! | AO23: =IF(Pivots!#REF!=" ",0,Pivots!#REF!) -> #REF! | AP23: =IF(Pivots!#REF!=" ",0,Pivots!#REF!) -> #REF! | AQ23: =IF(Pivots!#REF!=" ",0,Pivots!#REF!) -> #REF! | AR23: =IF(Pivots!#REF!=" ",0,Pivots!#REF!) -> #REF!
AM25: =IF(Pivots!#REF!=" ",0,Pivots!#REF!) -> #REF! | AN25: =IF(Pivots!#REF!=" ",0,Pivots!#REF!) -> #REF! | AO25: =IF(Pivots!#REF!=" ",0,Pivots!#REF!) -> #REF! | AP25: =IF(Pivots!#REF!=" ",0,Pivots!#REF!) -> #REF! | AQ25: =IF(Pivots!#REF!=" ",0,Pivots!#REF!) -> #REF! | AR25: =IF(Pivots!#REF!=" ",0,Pivots!#REF!) -> #REF!

Sheet Pivots
A3: Sample Count | B3: Total Processing Time (Min) | C3: Valid Test Count | D3: Delivered to EHR Count | E3: Invalid Test Count | F3: Undelivered to EHR Count | G3: Analytical Success Rate | H3: Delivered to EHR Rate | I3: Analytical Failure Rate | J3: Undelivered to EHR Rate | K3: Average Processing Time (Min) | L3: Average Integration Latency (Min) | M3: Valid Test Critical Latency Count | N3: Valid Test Delayed Sync Latency Count | O3: Avg Invalid Run Duration (Min) | P3: Avg Invalid Integration Latency (Min)
A4: 1000 | B4: 36913 | C4: 921 | D4: 921 | E4: 79 | F4: 79 | G4: 0.921 | H4: 0.921 | I4: 0.079 | J4: 0.079 | K4: 36.913 | L4: 3.233 | M4: 0 | N4: 0 | O4: 39.556962 | P4: 24.278481
A7: Sample Count | B7: Total Processing Time (Min) | C7: Valid Test Count | D7: Delivered to EHR Count | E7: Invalid Test Count | F7: Undelivered to EHR Count | G7: Analytical Success Rate | H7: Delivered to EHR Rate | I7: Analytical Failure Rate | J7: Undelivered to EHR Rate | K7: Average Processing Time (Min) | L7: Average Integration Latency (Min) | M7: Valid Test Critical Latency Count | N7: Valid Test Delayed Sync Latency Count | O7: Avg Invalid Run Duration (Min) | P7: Avg Invalid Integration Latency (Min)
A8: 341 | B8: 5838 | C8: 321 | D8: 321 | E8: 20 | F8: 20 | G8: 0.94134897 | H8: 0.94134897 | I8: 0.058651026 | J8: 0.058651026 | K8: 17.120235 | L8: 2.7800587 | M8: 0 | N8: 0 | O8: 16 | P8: 25.45
A11: Row Labels | B11: Delivered to EHR Count | C11: Undelivered to EHR Count | E11: For KPI: | F11: Delivered to EHR Count | G11: Undelivered to EHR Count
A12: Critical Error | C12: 20 | E12: Invalid | F12: =IF(B12=" ",0,B12) -> 0 | G12: =IF(C12=" ",0,C12) -> 20
A13: Valid | B13: 321 | E13: Valid | F13: =IF(B13=" ",0,B13) -> 321 | G13: =IF(C13=" ",0,C13) -> 0
A14: Grand Total | B14: 321 | C14: 20
A17: Row Labels | B17: Delivered to EHR Rate | C17: Undelivered to EHR Rate | E17: For KPI: | F17: Delivered to EHR Rate | G17: Undelivered to EHR Rate
A18: Critical Error | C18: 1 | E18: Invalid | F18: =IF(B18=" ",0,B18) -> 0 | G18: =IF(C18=" ",0,C18) -> 1
A19: Valid | B19: 1 | E19: Valid | F19: =IF(B19=" ",0,B19) -> 1 | G19: =IF(C19=" ",0,C19) -> 0
A20: Grand Total | B20: 0.94134897 | C20: 0.058651026
A23: Row Labels | B23: Tests Over Latency SLA | C23: Test Under Latency SLA | E23: For KPI: | F23: Tests Over Latency SLA | G23: Tests Under Latency SLA
A24: Critical Error | B24: 20 | E24: Invalid | F24: =IF(B24=" ",0,B24) -> 20 | G24: =IF(C24=" ",0,C24) -> 0
A25: Valid | C25: 321 | E25: Valid | F25: =IF(B25=" ",0,B25) -> 0 | G25: =IF(C25=" ",0,C25) -> 321
A26: Grand Total | B26: 20 | C26: 321
A29: Row Labels | B29: Tests Over Latency SLA Rate | C29: Tests Under Latency SLA Rate | E29: For KPI: | F29: Tests Over Latency SLA | G29: Tests Under Latency SLA
A30: Critical Error | B30: 1 | E30: Invalid | F30: =IF(B30=" ",0,B30) -> 1 | G30: =IF(C30=" ",0,C30) -> 0
A31: Valid | C31: 1 | E31: Valid | F31: =IF(B31=" ",0,B31) -> 0 | G31: =IF(C31=" ",0,C31) -> 1
A32: Grand Total | B32: 0.058651026 | C32: 0.94134897
A35: Row Labels | B35: Target Processing Time | C35: Average Processing Time (Min) | D35: Under Target Processing Time | E35: Over Target Processing Time | G35: For Chart (vs. Target): | H35: Analyzer Check | I35: Analyzer | J35: Avg. Processing Time | K35: Target Processing Time Check | L35: Target Processing Time | M35: Analyzer Under Target | N35: Analyzer Over Target
A36: Beckman Coulter | B36: 50 | H36: =A36 -> Beckman Coulter | I36: =IF(AND(C36="", D36=""), "", A36) | J36: =C36 -> 0 | K36: =B36 -> 50 | L36: {=_xlfn.IFS(I36=$H$40,K36,I36=$I$40,K36,I36=$J$40,K36)} -> #N/A | M36: =IF(J36<=L36,J36,NA()) -> #N/A | N36: =IF(J36>L36,J36,NA()) -> #N/A
A37: Abbott Alinity | B37: 20 | C37: 17.120235 | D37: 17.120235 | H37: =A37 -> Abbott Alinity | I37: =IF(AND(C37="", D37=""), "", A37) -> Abbott Alinity | J37: =C37 -> 17.120235 | K37: =B37 -> 20 | L37: {=_xlfn.IFS(I37=$H$40,K37,I37=$I$40,K37,I37=$J$40,K37)} -> 20 | M37: =IF(J37<=L37,J37,NA()) -> 17.120235 | N37: =IF(J37>L37,J37,NA()) -> #N/A
A38: Roche Cobas 8000 | B38: 35 | H38: =A38 -> Roche Cobas 8000 | I38: =IF(AND(C38="", D38=""), "", A38) | J38: =C38 -> 0 | K38: =B38 -> 35 | L38: {=_xlfn.IFS(I38=$H$40,K38,I38=$I$40,K38,I38=$J$40,K38)} -> #N/A | M38: =IF(J38<=L38,J38,NA()) -> #N/A | N38: =IF(J38>L38,J38,NA()) -> #N/A
A39: Grand Total | B39: 35 | C39: 17.120235 | D39: 17.120235
G40: Selected | H40: =A43 -> Abbott Alinity | I40: =A44 -> 0 | J40: =A45 -> 0
A42: Row Labels
A43: Abbott Alinity
A48: Sample Count | B48: Column Labels
A49: Row Labels | B49: Critical | C49: Delayed Sync | D49: Normal | E49: Grand Total | G49: For Chart (Latency Breakdown): | H49: Test Run | I49: Critical Latency | J49: Delayed Sync | K49: Normal Latency
A50: Critical Error | B50: 18 | C50: 2 | E50: 20 | H50: Invalid | I50: =IF(B50=0,NA(),B50) -> 18 | J50: =IF(C50=0,NA(),C50) -> 2 | K50: =IF(D50=0,NA(),D50) -> #N/A
A51: Valid | D51: 321 | E51: 321 | H51: Valid | I51: =IF(B51=0,NA(),B51) -> #N/A | J51: =IF(C51=0,NA(),C51) -> #N/A | K51: =IF(D51=0,NA(),D51) -> 321
A52: Grand Total | B52: 18 | C52: 2 | D52: 321 | E52: 341
A55: Row Labels | B55: Sample Count | C55: Sample Count2 | D55: Analytical Failure Rate
A56: Monday | B56: 75 | C56: 75 | D56: 0.08
A57: Tuesday | B57: 70 | C57: 70 | D57: 0.057142857
A58: Wednesday | B58: 69 | C58: 69 | D58: 0.028985507
A59: Thursday | B59: 67 | C59: 67 | D59: 0.074626866
A60: Friday | B60: 60 | C60: 60 | D60: 0.05
A61: Grand Total | B61: 341 | C61: 341 | D61: 0.058651026
...

Sheet Lab_Data
A1: Laboratory Data
A3: Sample ID | B3: Analyzer Module | C3: Processing Time (Min) | D3: Integration Latency (Min) | E3: Latency Severity | F3: Test Profile | G3: Data Quality Flag | H3: Verified To EHR | I3: Verified & Quality Flag Cross-Check | J3: Transaction_Date | K3: Day of Week
A4: S-1001 | B4: Abbott Alinity | C4: 24 | D4: 1 | E4: Normal | F4: Lipid Panel | G4: Valid | H4: Yes | I4: Consistent | J4: 46174 | K4: Monday
A5: S-1002 | B5: Beckman Coulter | C5: 55 | D5: 3 | E5: Normal | F5: Lipid Panel | G5: Valid | H5: Yes | I5: Consistent | J5: 46174 | K5: Monday
A6: S-1003 | B6: Roche Cobas 8000 | C6: 40 | D6: 0 | E6: Normal | F6: Comprehensive Metabolic | G6: Valid | H6: Yes | I6: Consistent | J6: 46174 | K6: Monday
A7: S-1004 | B7: Beckman Coulter | C7: 47 | D7: 1 | E7: Normal | F7: Thyroid Panel | G7: Valid | H7: Yes | I7: Consistent | J7: 46174 | K7: Monday
A8: S-1005 | B8: Abbott Alinity | C8: 18 | D8: 2 | E8: Normal | F8: Thyroid Panel | G8: Valid | H8: Yes | I8: Consistent | J8: 46174 | K8: Monday
A9: S-1006 | B9: Roche Cobas 8000 | C9: 43 | D9: 0 | E9: Normal | F9: Complete Blood Count | G9: Valid | H9: Yes | I9: Consistent | J9: 46174 | K9: Monday
A10: S-1007 | B10: Roche Cobas 8000 | C10: 37 | D10: 1 | E10: Normal | F10: Comprehensive Metabolic | G10: Valid | H10: Yes | I10: Consistent | J10: 46174 | K10: Monday
A11: S-1008 | B11: Abbott Alinity | C11: 13 | D11: 0 | E11: Normal | F11: Thyroid Panel | G11: Valid | H11: Yes | I11: Consistent | J11: 46174 | K11: Monday
A12: S-1009 | B12: Abbott Alinity | C12: 17 | D12: 4 | E12: Normal | F12: Comprehensive Metabolic | G12: Valid | H12: Yes | I12: Consistent | J12: 46174 | K12: Monday
A13: S-1010 | B13: Abbott Alinity | C13: 23 | D13: 0 | E13: Normal | F13: Thyroid Panel | G13: Valid | H13: Yes | I13: Consistent | J13: 46174 | K13: Monday
A14: S-1011 | B14: Roche Cobas 8000 | C14: 48 | D14: 1 | E14: Normal | F14: Comprehensive Metabolic | G14: Valid | H14: Yes | I14: Consistent | J14: 46174 | K14: Monday
A15: S-1012 | B15: Beckman Coulter | C15: 46 | D15: 1 | E15: Normal | F15: Lipid Panel | G15: Valid | H15: Yes | I15: Consistent | J15: 46174 | K15: Monday
... A1003: S-2000 | B1003: Roche Cobas 8000 | C1003: 33 | D1003: 1 | E1003: Normal | F1003: Complete Blood Count | G1003: Valid | H1003: Yes | I1003: Consistent | J1003: 46178 | K1003: Friday

Sheet Machine_SLA
A1: Analyzer Information
A3: Analyzer Module | B3: Target Processing Time | C3: Hardware Version | D3: Support Vendor
A4: Roche Cobas 8000 | B4: 35 | C4: v4.2 | D4: Roche Diagnostics
A5: Abbott Alinity | B5: 20 | C5: v2.1 | D5: Abbott Laboratories
A6: Beckman Coulter | B6: 50 | C6: v5.0 | D6: Beckman Health
